# 13.2 執行時異常和 panic

當發生像陣列下標越界或型別斷言失敗這樣的執行錯誤時，Go 執行時會觸發*執行時 panic*，伴隨着程式的崩潰丟擲一個 `runtime.Error` 介面型別的值。這個錯誤值有個 `RuntimeError()` 方法用於區別普通錯誤。

`panic` 可以直接從程式碼初始化：當錯誤條件（我們所測試的程式碼）很嚴苛且不可恢復，程式不能繼續執行時，可以使用 `panic` 函式產生一箇中止程式的執行時錯誤。`panic` 接收一個做任意型別的引數，通常是字串，在程式死亡時被列印出來。Go 執行時負責中止程式並給出除錯資訊。在示例 13.2 [panic.go](examples/chapter_13/panic.go) 中闡明瞭它的工作方式：

```go
package main

import "fmt"

func main() {
	fmt.Println("Starting the program")
	panic("A severe error occurred: stopping the program!")
	fmt.Println("Ending the program")
}
```

輸出如下：

```
Starting the program
panic: A severe error occurred: stopping the program!
panic PC=0x4f3038
runtime.panic+0x99 /go/src/pkg/runtime/proc.c:1032
       runtime.panic(0x442938, 0x4f08e8)
main.main+0xa5 E:/Go/GoBoek/code examples/chapter 13/panic.go:8
       main.main()
runtime.mainstart+0xf 386/asm.s:84
       runtime.mainstart()
runtime.goexit /go/src/pkg/runtime/proc.c:148
       runtime.goexit()
---- Error run E:/Go/GoBoek/code examples/chapter 13/panic.exe with code Crashed
---- Program exited with code -1073741783
```

一個檢查程式是否被已知使用者啟動的具體例子：

```go
var user = os.Getenv("USER")

func check() {
	if user == "" {
		panic("Unknown user: no value for $USER")
	}
}
```

可以在匯入包的 init() 函式中檢查這些。

當發生錯誤必須中止程式時，`panic` 可以用於錯誤處理模式：

```go
if err != nil {
	panic("ERROR occurred:" + err.Error())
}
```

<u>Go panicking</u>：

在多層巢狀的函式呼叫中呼叫 panic，可以馬上中止當前函式的執行，所有的 defer 語句都會保證執行並把控制權交還給接收到 panic 的函式呼叫者。這樣向上冒泡直到最頂層，並執行（每層的） defer，在棧頂處程式崩潰，並在命令列中用傳給 panic 的值報告錯誤情況：這個終止過程就是 *panicking*。

標準庫中有許多包含 `Must` 字首的函式，像 `regexp.MustComplie` 和 `template.Must`；當正規表示式或模板中轉入的轉換字串導致錯誤時，這些函式會 panic。

不能隨意地用 panic 中止程式，必須盡力補救錯誤讓程式能繼續執行。

## 連結

- [目錄](directory.md)
- 上一節：[錯誤處理](13.1.md)
- 下一節：[從 panic 中恢復（Recover）](13.3.md)