# 13.5 一種用閉包處理錯誤的模式

每當函式返回時，我們應該檢查是否有錯誤發生：但是這會導致重複乏味的程式碼。結合 defer/panic/recover 機制和閉包可以得到一個我們馬上要討論的更加優雅的模式。不過這個模式只有當所有的函式都是同一種簽名時可用，這樣就有相當大的限制。一個很好的使用它的例子是 web 應用，所有的處理函式都是下面這樣：

```go
func handler1(w http.ResponseWriter, r *http.Request) { ... }
```

假設所有的函式都有這樣的簽名：

```go
func f(a type1, b type2)
```

引數的數量和型別是不相關的。

我們給這個型別一個名字：

```go
fType1 = func f(a type1, b type2)
```

在我們的模式中使用了兩個幫助函式：

1）check：這是用來檢查是否有錯誤和 panic 發生的函式：

```go
func check(err error) { if err != nil { panic(err) } }
```

2）errorhandler：這是一個包裝函式。接收一個 fType1 型別的函式 fn 並返回一個呼叫 fn 的函式。裏面就包含有 defer/recover 機制，這在 [13.3 節](13.3.md)中有相應描述。

```go
func errorHandler(fn fType1) fType1 {
	return func(a type1, b type2) {
		defer func() {
			if err, ok := recover().(error); ok {
				log.Printf("run time panic: %v", err)
			}
		}()
		fn(a, b)
	}
}
```

當錯誤發生時會 recover 並列印在日誌中；除了簡單的列印，應用也可以用 template 包（參見 [15.7 節](15.7.md)）為使用者生成自定義的輸出。check() 函式會在所有的被調函式中呼叫，像這樣：

```go
func f1(a type1, b type2) {
	...
	f, _, err := // call function/method
	check(err)
	t, err := // call function/method
	check(err)
	_, err2 := // call function/method
	check(err2)
	...
}
```

通過這種機制，所有的錯誤都會被 recover，並且呼叫函式後的錯誤檢查程式碼也被簡化為呼叫 check(err) 即可。在這種模式下，不同的錯誤處理必須對應不同的函式型別；它們（錯誤處理）可能被隱藏在錯誤處理包內部。可選的更加通用的方式是用一個空介面型別的切片作為引數和返回值。

我們會在 [15.5 節](15.5.md)的 web 應用中使用這種模式。

<u>練習</u>

**練習 13.1**：[recover_dividebyzero.go](exercises/chapter_13/recover_divbyzero.go)

用示例 13.3 中的編碼模式通過整數除以 0 觸發一個執行時 panic。

**練習 13.2**：[panic_defer.go](exercises/chapter_13/panic_defer.go)

閲讀下面的完整程式。不要執行它，寫出程式的輸出結果。然後編譯執行並驗證你的預想。

```go
// panic_defer.go
package main

import "fmt"

func main() {
	f()
	fmt.Println("Returned normally from f.")
}

func f() {
	defer func() {
		if r := recover(); r != nil {
			fmt.Println("Recovered in f", r)
		}
	}()
	fmt.Println("Calling g.")
	g(0)
	fmt.Println("Returned normally from g.")
}

func g(i int) {
	if i > 3 {
		fmt.Println("Panicking!")
		panic(fmt.Sprintf("%v", i))
	}
	defer fmt.Println("Defer in g", i)
	fmt.Println("Printing in g", i)
	g(i + 1)
}
```

輸出：

```
Calling g.
Printing in g 0
Printing in g 1
Printing in g 2
Printing in g 3
Panicking!
Defer in g 3
Defer in g 2
Defer in g 1
Defer in g 0
Recovered in f 4
Returned normally from f.
```

**練習 13.3**：[panic_defer_convint.go](exercises/chapter_13/panic_defer_convint.go)

寫一個 ConvertInt64ToInt 函式把 int64 值轉換為 int 值，如果發生錯誤（提示：參見 [4.5.2.1 節](04.5.md#4521-整型-int-和浮點型-float)）就 panic。然後在函式 IntFromInt64 中呼叫這個函式並 recover，返回一個整數和一個錯誤。請測試這個函式！

## 連結

- [目錄](directory.md)
- 上一節：[自定義包中的錯誤處理和 panicking](13.4.md)
- 下一節：[啟動外部命令和程式](13.6.md)