# 14.6 協程和恢復（recover）

一個用到 `recover` 的程式（參見第 13.3 節）停掉了伺服器內部一個失敗的協程而不影響其他協程的工作。

```go
func server(workChan <-chan *Work) {
    for work := range workChan {
        go safelyDo(work)   // start the goroutine for that work
    }
}

func safelyDo(work *Work) {
    defer func() {
        if err := recover(); err != nil {
            log.Printf("Work failed with %s in %v", err, work)
        }
    }()
    do(work)
}
```

上邊的程式碼，如果 `do(work)` 發生 panic，錯誤會被記錄且協程會退出並釋放，而其他協程不受影響。

因為 `recover` 總是返回 `nil`，除非直接在 `defer` 修飾的函式中呼叫，`defer` 修飾的程式碼可以呼叫那些自身可以使用 `panic` 和 `recover` 避免失敗的庫例程（庫函式）。舉例，`safelyDo()` 中 `defer` 修飾的函式可能在呼叫 `recover` 之前就呼叫了一個 `logging` 函式，`panicking` 狀態不會影響 `logging` 程式碼的執行。因為加入了恢復模式，函式 `do`（以及它呼叫的任何東西）可以通過呼叫 `panic` 來擺脱不好的情況。但是恢復是在 `panicking` 的協程內部的：不能被另外一個協程恢復。


## 連結

- [目錄](directory.md)
- 上一節：[通道，超時和計時器](14.5.md)
- 下一節：[對比新舊模型：任務和工作](14.7.md)